Workbook

Sheet Tabelle1
A1: Bauvorhaben: | C1: 20006551 Offenbach, LEIQ | F1: Bieter: | G1: Sybotec | H1: Bieter: | I1: FBZ | J1: Bieter: | K1: Wellhöfer | L1: Bieter: | M1: Böhmler | N1: Bieter: | O1: Straehuber | P1: Bieter: | Q1: Akbo | R1: Bieter: | S1: Centerra | T1: Bieter: | U1: Rose | V1: Bieter:
F2: Tel: | G2: 09355-9705840 | H2: Tel: | I2: 069-782964 | J2: Tel: | K2: 069-95094880 | L2: Tel: | M2: 069-366012172 | N2: Tel: | O2: 06171-6941210 | P2: Tel: | Q2: 06151-1590050 | R2: Tel: | S2: 06204-6082354 | T2: Tel: | U2: 06441-5290120 | V2: Tel:
A3: Gewerk: | C3: Bodenbelag | F3: Angebot v.: | G3: 44698 | H3: Angebot v.: | I3: 44704 | J3: Angebot v.: | K3: 44705 | L3: Angebot v.: | M3: 44699 | N3: Angebot v.: | O3: 44704 | P3: Angebot v.: | Q3: 44699 | R3: Angebot v.: | S3: 44702 | T3: Angebot v.: | U3: 44702 | V3: Angebot v.:
F4: CR Auskunft: | H4: CR Auskunft: | J4: CR Auskunft: | L4: CR Auskunft: | N4: CR Auskunft: | P4: CR Auskunft: | R4: CR Auskunft: | T4: CR Auskunft: | V4: CR Auskunft:
F5: vom: | G5: Index | H5: vom: | I5: Index | J5: vom: | K5: Index | L5: vom: | M5: Index | N5: vom: | O5: Index | P5: vom: | Q5: Index | R5: vom: | S5: Index | T5: vom: | U5: Index | V5: vom: | W5: Index
F6: 44644 | G6: 207 | H6: 44715 | I6: 244 | J6: 44713 | K6: 195 | L6: 44638 | M6: 188 | N6: 44663 | O6: 228
F7: AK | G7: Umsatz | H7: AK | I7: Umsatz | J7: AK | K7: Umsatz | L7: AK | M7: Umsatz | N7: AK | O7: Umsatz | P7: AK | Q7: Umsatz | R7: AK | S7: Umsatz | T7: AK | U7: Umsatz | V7: AK | W7: Umsatz
F8: 13 | G8: ? | H8: 6 | I8: ? | J8: 9 | K8: 3.5 Mio | L8: 204 | M8: 66 Mio | N8: 60 | O8: 6.641 Mio
A9: Pos. | B9: Kurz-Info | C9: Beschreibung | D9: Menge | E9: EH | F9: EP | G9: GP | H9: EP | I9: GP | J9: EP | K9: GP | L9: EP | M9: GP | N9: EP | O9: GP | P9: EP | Q9: GP | R9: EP | S9: GP | T9: EP | U9: GP | V9: EP | W9: GP
F10: Siehe Angebot! | J10: Siehe Angebot! | L10: Siehe Angebot! | N10: Siehe Angebot!
A11: 01.01. | C11: Bodenbelagsarbeiten Bauteil A
A12: 01.01.01.010 | C12: Untergrund vorbereiten, grundieren, Ausgleichsmasse, Hohlraumboden | D12: 5742 | E12: m² | F12: 2.8 | G12: =$D12*F12 -> 16077.6 | H12: 2.85 | I12: =$D12*H12 -> 16364.7 | J12: 2.44 | K12: =$D12*J12 -> 14010.48 | L12: 5.65 | M12: =$D12*L12 -> 32442.3 | N12: 5.1 | O12: =$D12*N12 -> 29284.2 | P12: 5.5 | Q12: =$D12*P12 -> 31581 | R12: 4.87 | S12: =$D12*R12 -> 27963.54 | T12: 6 | U12: =$D12*T12 -> 34452 | V12: 0 | W12: =$D12*V12 -> 0
A13: 01.01.01.020 | C13: Textilbelag, Fliesen, Schlinge, getuftet, synthetisch, 50x50cm, Dolomite | D13: 4430 | E13: m² | F13: 35.75 | G13: =$D13*F13 -> 158372.5 | H13: 34.84 | I13: =$D13*H13 -> 154341.2 | J13: 37.33 | K13: =$D13*J13 -> 165371.9 | L13: 36 | M13: =$D13*L13 -> 159480 | N13: 38.4 | O13: =$D13*N13 -> 170112 | P13: 36.8 | Q13: =$D13*P13 -> 163024 | R13: 37.34 | S13: =$D13*R13 -> 165416.2 | T13: 38 | U13: =$D13*T13 -> 168340 | V13: 0 | W13: =$D13*V13 -> 0
A14: 01.01.01.030 | C14: Textilbelag, Fliesen, Schlinge, getuftet, synthetisch, 50x50cm, Touch & Tones 102 | D14: 1313 | E14: m² | F14: 48.1 | G14: =$D14*F14 -> 63155.3 | H14: 46.75 | I14: =$D14*H14 -> 61382.75 | J14: 49.95 | K14: =$D14*J14 -> 65584.35 | L14: 49.55 | M14: =$D14*L14 -> 65059.15 | N14: 52.7 | O14: =$D14*N14 -> 69195.1 | P14: 47.5 | Q14: =$D14*P14 -> 62367.5 | R14: 49.59 | S14: =$D14*R14 -> 65111.67 | T14: 50 | U14: =$D14*T14 -> 65650 | V14: 0 | W14: =$D14*V14 -> 0
A15: 01.01.01.040 | B15: Bo,XA | C15: Zulage, Akustikrücken, T&T II 101 ReCushionbac | D15: 1 | E15: m² | F15: 5.1 | G15: NEP | H15: 4.25 | I15: NEP | J15: 44.44 | K15: NEP | L15: 5.05 | M15: NEP | N15: 5.3 | O15: NEP | P15: 8.5 | Q15: NEP | R15: 6.5 | S15: NEP | T15: 10 | U15: NEP | V15: 0 | W15: NEP
A16: 01.01.01.050 | B16: Bo,XA | C16: Zulage, Akustikrücken, T&T II 102 ReCushionbac | D16: 1 | E16: m² | F16: 5.1 | G16: NEP | H16: 4.25 | I16: NEP | J16: 53 | K16: NEP | L16: 5.05 | M16: NEP | N16: 5.3 | O16: NEP | P16: 11.5 | Q16: NEP | R16: 6.5 | S16: NEP | T16: 10 | U16: NEP | V16: 0 | W16: NEP
A17: 01.01.01.060 | B17: Bo,XA | C17: Aussparung, Bodentanks im Teppich-Belag, b=250mm | D17: 385 | E17: St | F17: 5.65 | G17: NEP | H17: 5.35 | I17: NEP | J17: 4 | K17: NEP | L17: 1.25 | M17: NEP | N17: 5.8 | O17: NEP | P17: 5 | Q17: NEP | R17: 4.42 | S17: NEP | T17: 10 | U17: NEP | V17: 0 | W17: NEP
A18: 01.01.01.070 | B18: Bo,XA | C18: Aussparung Revisionsöffnung, 600/600 mm, mit Teppich belegen | D18: 1 | E18: St | F18: 12.4 | G18: NEP | H18: 4.5 | I18: NEP | J18: 4 | K18: NEP | L18: 1.85 | M18: NEP | N18: nicht notwendig | O18: NEP | P18: 8.5 | Q18: NEP | R18: 9.66 | S18: NEP | T18: 30 | U18: NEP | V18: 0 | W18: NEP
A19: 01.01.01.080 | C19: Sockelleiste, Textilbelag, gekettelt, h=50 mm, geklebt, | D19: 3923 | E19: m | H19: 5.9 | I19: =$D19*H19 -> 23145.7 | N19: 5.5 | O19: =$D19*N19 -> 21576.5 | P19: 5.5 | Q19: =$D19*P19 -> 21576.5 | R19: 6.57 | S19: =$D19*R19 -> 25774.11 | T19: 10 | U19: =$D19*T19 -> 39230 | V19: 0 | W19: =$D19*V19 -> 0
C20: Sockelleiste, Textilbelag, gekettelt, h=50 mm, geklebt, zu Fabr. Dolomite | D20: 3923 | E20: m | F20: 4.85 | G20: =$D20*F20 -> 19026.55 | J20: 5.2 | K20: =$D20*J20 -> 20399.6 | L20: 5.2 | M20: =$D20*L20 -> 20399.6
C21: Sockelleiste, Textilbelag, gekettelt, h=50 mm, geklebt zu Fabr. touch&tones | D21: 3923 | E21: m | F21: 5.7 | G21: NEP | J21: 6.8 | K21: NEP
A22: 01.01.01.090 | B22: Bo,XA | C22: Sockelleiste, Textilbelag, gekettelt, h=70 mm, geklebt | D22: 1 | E22: m | H22: 6.9 | I22: NEP | J22: k. Angebot | K22: NEP | N22: 6.75 | O22: NEP | P22: 7.5 | Q22: NEP | R22: 7.1 | S22: NEP | T22: 12 | U22: NEP | V22: 0 | W22: NEP
C23: Sockelleiste, Textilbelag, gekettelt, h=70 mm, geklebt, zu Fabr. Dolomite | D23: 1 | E23: m | F23: 6 | G23: NEP | L23: 5.95 | M23: NEP
C24: Sockelleiste, Textilbelag, gekettelt, h=70 mm, geklebt zu Fabr. touch&tones | D24: 1 | E24: m | F24: 7.1 | G24: NEP
A25: 01.01.01.100 | B25: Bo,XA | C25: Übergangsprofil für Belag, Aluminium eloxiert, b=30 mm | D25: 1 | E25: m | F25: 13.8 | G25: NEP | H25: 14.9 | I25: NEP | J25: 24 | K25: NEP | L25: 7.25 | M25: NEP | N25: 13.15 | O25: NEP | P25: 15.5 | Q25: NEP | R25: 11.5 | S25: NEP | T25: 18 | U25: NEP | V25: 0 | W25: NEP
A26: 01.01.01.110 | B26: Bo,XA | C26: Übergangsprofil für Belag, Messing, b=30mm | D26: 1 | E26: m | F26: 16.7 | G26: NEP | H26: 19.9 | I26: NEP | J26: k. Angebot | K26: NEP | L26: 13.95 | M26: NEP | N26: 18.95 | O26: NEP | P26: 15.5 | Q26: NEP | R26: 12.75 | S26: NEP | T26: 18 | U26: NEP | V26: 0 | W26: NEP
A27: 01.01.01. | C27: Teppichboden | G27: =SUM(G12:G26) -> 256631.95 | I27: =SUM(I12:I26) -> 255234.35 | K27: =SUM(K12:K26) -> 265366.33 | M27: =SUM(M12:M26) -> 277381.05 | O27: =SUM(O12:O26) -> 290167.8 | Q27: =SUM(Q12:Q26) -> 278549 | S27: =SUM(S12:S26) -> 284265.52 | U27: =SUM(U12:U26) -> 307672 | W27: =SUM(W12:W26) -> 0
A29: 01.01.02.010 | C29: Untergrund vorbereiten, grundieren, Ausgleichsmasse, Hohlraumboden | D29: 1885 | E29: m² | F29: 3.6 | G29: =$D29*F29 -> 6786 | H29: 7.75 | I29: =$D29*H29 -> 14608.75 | J29: 6.8 | K29: =$D29*J29 -> 12818 | L29: 5.65 | M29: =$D29*L29 -> 10650.25 | N29: 5.1 | O29: =$D29*N29 -> 9613.5 | P29: 6.5 | Q29: =$D29*P29 -> 12252.5 | R29: 5.27 | S29: =$D29*R29 -> 9933.95 | T29: 6 | U29: =$D29*T29 -> 11310 | V29: 0 | W29: =$D29*V29 -> 0
A30: 01.01.02.020 | C30: Fußbodenbelag, Vinyl, elastisch, d=4,5 mm, 50x50 cm, | D30: 1885 | E30: m² | F30: 38.15 | G30: =$D30*F30 -> 71912.75 | H30: 37.69 | I30: =$D30*H30 -> 71045.65 | J30: 37 | K30: =$D30*J30 -> 69745 | L30: 41.45 | M30: =$D30*L30 -> 78133.25 | N30: 40.15 | O30: =$D30*N30 -> 75682.75 | P30: 38.8 | Q30: =$D30*P30 -> 73138 | R30: 40.33 | S30: =$D30*R30 -> 76022.05 | T30: 41 | U30: =$D30*T30 -> 77285 | V30: 0 | W30: =$D30*V30 -> 0
A31: 01.01.02.030 | C31: Sockelleiste, PVC-weich, 50 mm | D31: 1351 | E31: m | F31: 3.45 | G31: =$D31*F31 -> 4660.95 | H31: 4.9 | I31: =$D31*H31 -> 6619.9 | J31: 5.6 | K31: =$D31*J31 -> 7565.6 | L31: 6.75 | M31: =$D31*L31 -> 9119.25 | N31: 4.8 | O31: =$D31*N31 -> 6484.8 | P31: 4.5 | Q31: =$D31*P31 -> 6079.5 | R31: 5 | S31: =$D31*R31 -> 6755 | T31: 7 | U31: =$D31*T31 -> 9457 | V31: 0 | W31: =$D31*V31 -> 0
A32: 01.01.02.040 | B32: Bo,XA | C32: Sockelleiste, Vinyl, Holzfaserkern, 50mm | D32: 1 | E32: m | F32: 3.85 | G32: NEP | H32: 5.9 | I32: NEP | J32: k. Angebot | K32: NEP | L32: 5.3 | M32: NEP | N32: 6.4 | O32: NEP | P32: 8.5 | Q32: NEP | R32: 7.45 | S32: NEP | T32: 10 | U32: NEP | V32: 0 | W32: NEP
A33: 01.01.02.050 | B33: Bo,XA | C33: Sockelleiste, Vinyl, auf MDF, 50 mm | D33: 1 | E33: m | F33: k. Angebot | G33: NEP | H33: 8.9 | I33: NEP | J33: k. Angebot | K33: NEP | L33: 9.5 | M33: NEP | N33: 7.95 | O33: NEP | P33: 8.5 | Q33: NEP | R33: 7.2 | S33: NEP | T33: 12.5 | U33: NEP | V33: 0 | W33: NEP
A34: 01.01.02.060 | C34: Erstpflege Vinyl-Bodenbelag und Sockelleisten | D34: 1885 | E34: m² | F34: 1.7 | G34: =$D34*F34 -> 3204.5 | H34: 3.9 | I34: =$D34*H34 -> 7351.5 | J34: k. Angebot | L34: 1.5 | M34: =$D34*L34 -> 2827.5 | N34: 2.05 | O34: =$D34*N34 -> 3864.25 | P34: 4.5 | Q34: =$D34*P34 -> 8482.5 | R34: 2.66 | S34: =$D34*R34 -> 5014.1 | T34: 3.8 | U34: =$D34*T34 -> 7163 | V34: 0 | W34: =$D34*V34 -> 0
A35: 01.01.02.070 | B35: Bo,XA | C35: Übergangsprofil, unter Türen | D35: 1 | E35: m | F35: 24.8 | G35: NEP | H35: 20.9 | I35: NEP | J35: 29 | K35: NEP | L35: 13.9 | M35: NEP | N35: 13.15 | O35: NEP | P35: 15.5 | Q35: NEP | R35: 11.5 | S35: NEP | T35: 18 | U35: NEP | V35: 0 | W35: NEP
A36: 01.01.02.080 | B36: Bo,XA | C36: Untergrund ausgleichen, 3-5mm, Übergangsbereich Vinylboden/Teppichboden | D36: 1 | E36: m² | F36: k. Angebot | G36: NEP | H36: 6.9 | I36: NEP | J36: 6.8 | K36: NEP | L36: 14.45 | M36: NEP | N36: 18.2 | O36: NEP | P36: 6.5 | Q36: NEP | R36: 7.65 | S36: NEP | T36: 18 | U36: NEP | V36: 0 | W36: NEP
A37: 01.01.02.090 | B37: Bo,XA | C37: Zulage, elastische Dämmunterlage, Höhenausgleich, d=3mm | D37: 1 | E37: m² | F37: 16.8 | G37: NEP | H37: 19.9 | I37: NEP | J37: k. Angebot | K37: NEP | L37: 19.75 | M37: NEP | N37: k. Angebot | O37: NEP | P37: 22.5 | Q37: NEP | R37: 17.04 | S37: NEP | T37: 25 | U37: NEP | V37: 0 | W37: NEP
A38: 01.01.02.100 | B38: Bo,XA | C38: Zulage, elastische Dämmunterlage, Höhenausgleich, d=4mm | D38: 1 | E38: m² | F38: k. Angebot | G38: NEP | H38: 21.9 | I38: NEP | J38: k. Angebot | K38: NEP | L38: 23.6 | M38: NEP | N38: k. Angebot | O38: NEP | P38: 23.5 | Q38: NEP | R38: 18.36 | S38: NEP | T38: 28 | U38: NEP | V38: 0 | W38: NEP
A39: 01.01.02. | C39: Vinyl Fußbodenbelag | G39: =SUM(G29:G38) -> 86564.2 | I39: =SUM(I29:I38) -> 99625.8 | K39: =SUM(K29:K38) -> 90128.6 | M39: =SUM(M29:M38) -> 100730.25 | O39: =SUM(O29:O38) -> 95645.3 | Q39: =SUM(Q29:Q38) -> 99952.5 | S39: =SUM(S29:S38) -> 97725.1 | U39: =SUM(U29:U38) -> 105215 | W39: =SUM(W29:W38) -> 0
A41: 01.01.03.010 | C41: Untergrund vorbereiten, grundieren, Ausgleichsmasse, Estrich | D41: 55 | E41: m² | F41: 5.6 | G41: =$D41*F41 -> 308 | H41: 7.75 | I41: =$D41*H41 -> 426.25 | J41: 6.8 | K41: =$D41*J41 -> 374 | L41: 5.65 | M41: =$D41*L41 -> 310.75 | N41: 5.1 | O41: =$D41*N41 -> 280.5 | P41: 8.5 | Q41: =$D41*P41 -> 467.5 | R41: 5.69 | S41: =$D41*R41 -> 312.95 | T41: 6 | U41: =$D41*T41 -> 330 | V41: 0 | W41: =$D41*V41 -> 0
A42: 01.01.03.020 | C42: Untergrund vorbereiten, grundieren, Ausgleichsmasse, Hohlraumboden | D42: 81 | E42: m² | F42: 5.6 | G42: =$D42*F42 -> 453.6 | H42: 7.75 | I42: =$D42*H42 -> 627.75 | J42: 6.8 | K42: =$D42*J42 -> 550.8 | L42: 5.65 | M42: =$D42*L42 -> 457.65 | N42: 5.1 | O42: =$D42*N42 -> 413.1 | P42: 8.5 | Q42: =$D42*P42 -> 688.5 | R42: 5.27 | S42: =$D42*R42 -> 426.87 | T42: 6 | U42: =$D42*T42 -> 486 | V42: 0 | W42: =$D42*V42 -> 0
...

Sheet Tabelle2
A1: Bauvorhaben: | C1: 20006551 Offenbach, LEIQ | F1: Bieter: | G1: Sybotec | H1: Bieter: | I1: FBZ | J1: Bieter: | K1: Wellhöfer | L1: Bieter: | M1: Böhmler | N1: Bieter: | O1: Straehuber
F2: Tel: | G2: 09355-9705840 | H2: Tel: | I2: 069-782964 | J2: Tel: | K2: 069-95094880 | L2: Tel: | M2: 069-366012172 | N2: Tel: | O2: 06171-6941210
A3: Gewerk: | C3: Bodenbelag | F3: Angebot v.: | G3: 44698 | H3: Angebot v.: | I3: 44704 | J3: Angebot v.: | K3: 44705 | L3: Angebot v.: | M3: 44699 | N3: Angebot v.: | O3: 44704
F4: CR Auskunft: | H4: CR Auskunft: | J4: CR Auskunft: | L4: CR Auskunft: | N4: CR Auskunft:
F5: vom: | G5: Index | H5: vom: | I5: Index | J5: vom: | K5: Index | L5: vom: | M5: Index | N5: vom: | O5: Index
F6: 44644 | G6: 207 | H6: 44715 | I6: 244 | J6: 44713 | K6: 195 | L6: 44638 | M6: 188 | N6: 44663 | O6: 228
F7: AK | G7: Umsatz | H7: AK | I7: Umsatz | J7: AK | K7: Umsatz | L7: AK | M7: Umsatz | N7: AK | O7: Umsatz
F8: 13 | G8: ? | H8: 6 | I8: ? | J8: 9 | K8: 3.5 Mio | L8: 204 | M8: 66 Mio | N8: 60 | O8: 6.641 Mio
A9: Pos. | B9: Kurz-Info | C9: Beschreibung | D9: Menge | E9: EH | F9: EP | G9: GP | H9: EP | I9: GP | J9: EP | K9: GP | L9: EP | M9: GP | N9: EP | O9: GP
J10: Siehe Angebot! | L10: Siehe Angebot!
A11: 01.01. | C11: Bodenbelagsarbeiten Bauteil A
A12: 01.01.01.010 | C12: Untergrund vorbereiten, grundieren, Ausgleichsmasse, Hohlraumboden | D12: 5742 | E12: m² | F12: =Tabelle1!F12 -> 2.8 | G12: =$D12*F12 -> 16077.6 | H12: =Tabelle1!H12 -> 2.85 | I12: =$D12*H12 -> 16364.7 | J12: 2.44 | K12: =$D12*J12 -> 14010.48 | L12: 5.65 | M12: =$D12*L12 -> 32442.3 | N12: 1.7 | O12: =$D12*N12 -> 9761.4
A13: 01.01.01.020 | C13: Textilbelag, Fliesen, Schlinge, getuftet, synthetisch, 50x50cm, Dolomite | D13: 4430 | E13: m² | F13: =Tabelle1!F13 -> 35.75 | G13: =$D13*F13 -> 158372.5 | H13: =Tabelle1!H13 -> 34.84 | I13: =$D13*H13 -> 154341.2 | J13: 37.33 | K13: =$D13*J13 -> 165371.9 | L13: 36 | M13: =$D13*L13 -> 159480 | N13: 37.5 | O13: =$D13*N13 -> 166125
A14: 01.01.01.030 | C14: Textilbelag, Fliesen, Schlinge, getuftet, synthetisch, 50x50cm, Touch & Tones 102 | D14: 1313 | E14: m² | F14: =Tabelle1!F14 -> 48.1 | G14: =$D14*F14 -> 63155.3 | H14: =Tabelle1!H14 -> 46.75 | I14: =$D14*H14 -> 61382.75 | J14: 49.95 | K14: =$D14*J14 -> 65584.35 | L14: 49.55 | M14: =$D14*L14 -> 65059.15 | N14: 51.54 | O14: =$D14*N14 -> 67672.02
A15: 01.01.01.040 | B15: Bo,XA | C15: Zulage, Akustikrücken, T&T II 101 ReCushionbac | D15: 1 | E15: m² | F15: =Tabelle1!F15 -> 5.1 | G15: NEP | H15: =Tabelle1!H15 -> 4.25 | I15: NEP | J15: 44.44 | K15: NEP | L15: 5.05 | M15: NEP | N15: 5.3 | O15: NEP
A16: 01.01.01.050 | B16: Bo,XA | C16: Zulage, Akustikrücken, T&T II 102 ReCushionbac | D16: 1 | E16: m² | F16: =Tabelle1!F16 -> 5.1 | G16: NEP | H16: =Tabelle1!H16 -> 4.25 | I16: NEP | J16: 53 | K16: NEP | L16: 5.05 | M16: NEP | N16: =Tabelle1!N16 -> 5.3 | O16: NEP
A17: 01.01.01.060 | B17: Bo,XA | C17: Aussparung, Bodentanks im Teppich-Belag, Du 305 mm, RUND! | D17: 385 | E17: St | F17: =Tabelle1!F17 -> 5.65 | G17: =$D17*F17 -> 2175.25 | H17: 6.1 | I17: =$D17*H17 -> 2348.5 | J17: 4 | K17: =$D17*J17 -> 1540 | L17: 1.25 | M17: NEP | N17: 5.8 | O17: =$D17*N17 -> 2233
A18: 01.01.01.070 | B18: Bo,XA | C18: Aussparung Revisionsöffnung, 600/600 mm, mit Teppich belegen | D18: 1 | E18: St | F18: =Tabelle1!F18 -> 12.4 | G18: NEP | H18: =Tabelle1!H18 -> 4.5 | I18: NEP | J18: 4 | K18: NEP | L18: 1.85 | M18: NEP | N18: =Tabelle1!N18 -> nicht notwendig | O18: NEP
A19: 01.01.01.080 | C19: Sockelleiste, Textilbelag, gekettelt, h=50 mm, geklebt, | D19: 3923 | E19: m | H19: =Tabelle1!H19 -> 5.9 | I19: NEP | K19: NEP | N19: =Tabelle1!N19 -> 5.5 | O19: NEP
A20: 01.01.01.080A | C20: Sockelleiste, Vollholz, weiß, 60 mm | D20: 3923 | E20: m | F20: 9.28 | G20: =$D20*F20 -> 36405.44 | H20: 6.35 | I20: =$D20*H20 -> 24911.05 | K20: =$D20*J20 -> 0 | N20: 6.95 | O20: =$D20*N20 -> 27264.85
C21: Sockelleiste,Vollholz, weiß, folienummantelt | D21: 3923 | E21: m | N21: 7.35 | O21: NEP
C22: Sockelleiste, MDF- Kern, 13*60 mm | D22: 1 | E22: m | F22: 5.88 | G22: NEP
C23: Sockelleiste, Textilbelag, gekettelt, h=50 mm, geklebt, zu Fabr. Dolomite | D23: 3923 | E23: m | F23: =Tabelle1!F20 -> 4.85 | G23: NEP | H23: =Tabelle1!H20 -> 0 | J23: 5.2 | L23: 5.2 | M23: =$D23*L23 -> 20399.6
C24: Sockelleiste, Textilbelag, gekettelt, h=50 mm, geklebt zu Fabr. touch&tones | D24: 3923 | E24: m | F24: =Tabelle1!F21 -> 5.7 | G24: NEP | H24: =Tabelle1!H21 -> 0 | J24: 6.8
A25: 01.01.01.090 | B25: Bo,XA | C25: Sockelleiste, Textilbelag, gekettelt, h=70 mm, geklebt | D25: 1 | E25: m | H25: =Tabelle1!H22 -> 6.9 | I25: NEP | J25: k. Angebot | K25: NEP | N25: =Tabelle1!N22 -> 6.75 | O25: NEP
C26: Sockelleiste, Textilbelag, gekettelt, h=50 mm, geklebt, zu Fabr. Dolomite | D26: 1 | E26: m | F26: =Tabelle1!F23 -> 6 | G26: NEP | H26: =Tabelle1!H23 -> 0 | L26: 5.95 | M26: NEP | N26: =Tabelle1!N23 -> 0
C27: Sockelleiste, Textilbelag, gekettelt, h=50 mm, geklebt zu Fabr. touch&tones | D27: 1 | E27: m | F27: =Tabelle1!F24 -> 7.1 | G27: NEP | H27: =Tabelle1!H24 -> 0 | N27: =Tabelle1!N24 -> 0
A28: 01.01.01.100 | B28: Bo,XA | C28: Übergangsprofil für Belag, Aluminium eloxiert, b=30 mm | D28: 1 | E28: m | F28: =Tabelle1!F25 -> 13.8 | G28: NEP | H28: =Tabelle1!H25 -> 14.9 | I28: NEP | J28: 24 | K28: NEP | L28: 7.25 | M28: NEP | N28: =Tabelle1!N25 -> 13.15 | O28: NEP
A29: 01.01.01.110 | B29: Bo,XA | C29: Übergangsprofil für Belag, Messing, b=30mm | D29: 1 | E29: m | F29: =Tabelle1!F26 -> 16.7 | G29: NEP | H29: =Tabelle1!H26 -> 19.9 | I29: NEP | J29: k. Angebot | K29: NEP | L29: 13.95 | M29: NEP | N29: =Tabelle1!N26 -> 18.95 | O29: NEP
A30: 01.01.01. | C30: Teppichboden | G30: =SUM(G12:G29) -> 276186.09 | I30: =SUM(I12:I29) -> 259348.2 | K30: =SUM(K12:K29) -> 246506.73 | M30: =SUM(M12:M29) -> 277381.05 | O30: =SUM(O12:O29) -> 273056.27
A32: 01.01.02.010 | C32: Untergrund vorbereiten, grundieren, Ausgleichsmasse, Hohlraumboden | D32: 1885 | E32: m² | F32: =Tabelle1!F29 -> 3.6 | G32: =$D32*F32 -> 6786 | H32: =Tabelle1!H29 -> 7.75 | I32: =$D32*H32 -> 14608.75 | J32: 6.8 | K32: =$D32*J32 -> 12818 | L32: 5.65 | M32: =$D32*L32 -> 10650.25 | N32: =Tabelle1!N29 -> 5.1 | O32: =$D32*N32 -> 9613.5
A33: 01.01.02.020 | C33: Fußbodenbelag, Vinyl, elastisch, d=4,5 mm, 50x50 cm, | D33: 1885 | E33: m² | F33: =Tabelle1!F30 -> 38.15 | G33: =$D33*F33 -> 71912.75 | H33: =Tabelle1!H30 -> 37.69 | I33: =$D33*H33 -> 71045.65 | J33: 37 | K33: =$D33*J33 -> 69745 | L33: 41.45 | M33: =$D33*L33 -> 78133.25 | N33: 38.5 | O33: =$D33*N33 -> 72572.5
C34: aus Titel 01.01.03 (Kautschukbelag) | D34: 81 | E34: m2 | F34: 38.15 | G34: =$D34*F34 -> 3090.15 | H34: 37.69 | I34: =$D34*H34 -> 3052.89 | J34: 37 | K34: =$D34*J34 -> 2997 | N34: 38.5 | O34: =$D34*N34 -> 3118.5
A35: 01.01.02.030 | C35: Sockelleiste, PVC-weich, 50 mm | D35: 1351 | E35: m | F35: =Tabelle1!F31 -> 3.45 | G35: NEP | H35: =Tabelle1!H31 -> 4.9 | I35: NEP | J35: 5.6 | K35: NEP | L35: 6.75 | M35: =$D35*L35 -> 9119.25 | N35: 3.72 | O35: NEP
A36: 01.01.02.030A | C36: Sockelleiste, Vollholz, weiß, 60 mm | D36: 1351 | E36: m | F36: 9.28 | G36: =$D36*F36 -> 12537.28 | H36: 8.3 | I36: =$D36*H36 -> 11213.3 | K36: =$D36*J36 -> 0 | N36: 6.95 | O36: =$D36*N36 -> 9389.45
C37: Sockelleiste,Vollholz, weiß, folienummantelt | D37: 1351 | E37: m | N37: 7.35 | O37: NEP
C38: Sockelleiste, MDF- Kern, 13*60 mm | D38: 1 | E38: m | F38: 5.88 | G38: NEP
A39: 01.01.02.040 | B39: Bo,XA | C39: Sockelleiste, Vinyl, Holzfaserkern, 50mm | D39: 1 | E39: m | F39: =Tabelle1!F32 -> 3.85 | G39: NEP | H39: =Tabelle1!H32 -> 5.9 | I39: NEP | J39: k. Angebot | K39: NEP | L39: 5.3 | M39: NEP | N39: =Tabelle1!N32 -> 6.4 | O39: NEP
A40: 01.01.02.050 | B40: Bo,XA | C40: Sockelleiste, Vinyl, auf MDF, 50 mm | D40: 1 | E40: m | F40: =Tabelle1!F33 -> k. Angebot | G40: NEP | H40: =Tabelle1!H33 -> 8.9 | I40: NEP | J40: k. Angebot | K40: NEP | L40: 9.5 | M40: NEP | N40: =Tabelle1!N33 -> 7.95 | O40: NEP
A41: 01.01.02.060 | C41: Erstpflege Vinyl-Bodenbelag und Sockelleisten | D41: 1885 | E41: m² | F41: =Tabelle1!F34 -> 1.7 | G41: =$D41*F41 -> 3204.5 | H41: =Tabelle1!H34 -> 3.9 | I41: =$D41*H41 -> 7351.5 | J41: k. Angebot | L41: 1.5 | M41: =$D41*L41 -> 2827.5 | N41: =Tabelle1!N34 -> 2.05 | O41: =$D41*N41 -> 3864.25
...
